Workbook

Sheet READ THIS - ABOUT THIS FILE
A1: WHATS IN THIS FILE?
B2: This file contains answer to the practice questions given in the associated Word document.
B3: The other two worksheets (i.e. "tabs") in this file contain the answers to Part I and Part II.
A5: ANSWERS TO PART I
B6: See answers on the "part1" tab.
A8: ANSWERS TO PART 2
B9: See answers on the "part2" tab.
B10: Make sure to read the NOTES section at the bottom of the "part2" tab for info relating to quesitons 2 and 3
B11: A summary of the correct formulas for the answers appears at the bottom of the "part2" tab.

Sheet part1-answers
A1: 1 | B1: 20 | C1: 100
A2: 2 | B2: 10 | C2: 300
A3: 3 | B3: 40 | C3: 200
A4: 4 | B4: 30 | C4: 400
A6: ANSWERS ARE AT THE BOTTOM OF THIS WORKSHEET | D6: FOR QUESTION 3 - look at the formulas in the cells below
D7: Formula in cell E7 ---> | E7: =F9+$F9+F$9+$F$9 -> 0
A8: DATA ABOVE IS USED IN THE FORMULAS | D8: was copied to cell G8 ---> | G8: =H10+$F10+H$9+$F$9 -> 0
A10: TO GET PARTIAL CREDIT ON QUESTIONS 1 and 2 YOU MUST SHOW HOW EXCEL CACLUATES THE ANSWER, STEP BY STEP.
B11: These questions are meant to be answered WITHOUT Excel.
B12: To get partial credit on questions 1 and 2, you must write how you got your answer. To do so, show the steps that Excel takes to get the answer.
B13: To see each step, you can click on the cell that contains a formula and the the "Evaluate Formula" button on the "Formulas" tab.
A17: ANSWERS (see below)
A19: QUESTION NUMBER | B19: ANSWER | C19: NOTES
A21: 1 | B21: =3+IF(SUM(AVERAGE(B1:B2),A4)<20,IF(A4>100,300,5),IF(A1>5,100,200))*3 -> 18 | C21: <<<--- To see the steps Excel takes to calculate, click on this cell, then press "Evaluate Formula" button on the "Formulas" tab.
A22: 2 | B22: =AND(B1>1,OR(B2>1000,B3>1000)) -> FALSE | C22: <<<--- To see the steps Excel takes to calculate, click on this cell, then press "Evaluate Formula" button on the "Formulas" tab.
A23: 3 | B23: =_xlfn.FORMULATEXT(G8) -> =H10+$F10+H$9+$F$9
A24: 4 | B24: On windows - press alt-ENTER
B25: On Mac - press Ctrl-Opt-ENTER or Opt-ENTER depending on your mac version.

Sheet part2-answers-inventory
A1: ANSWERS - THE ANSWERS CONSIST OF FORMULAS THAT ARE TYPED INTO THE YELLOW AND ORANGE CELLS. SEE NOTES AT THE BOTTOM OF THIS WORKSHEET.
B2: INSTRUCTIONS for Part II | K2: Vlookup table for question 9 | N2: Question 10
B3: This worksheet is filled in with plain data as well as with formulas. | K3: COLOR | L3: REDUCTION | N3: The numbers in the cells below are calculated with formulas. Write a
B4: The columns below that start with q1, q2, etc contain formulas. | K4: yellow | L4: 10 | N4: single formula to calculate the uppper left number. Write the formula
B5: Column q1 is for question 1, q2 is for question 2, etc. | K5: blue | L5: 0 | N5: so it can be copied to the other cells with numbers to calculate the
B6: See the test paper for specific instructions for each question. | K6: green | L6: 5 | N6: correct results.
B7: For each question you are to write the formula as it would appear in the first. | P7: shirt | Q7: pants | R7: jacket
B8: cell at the top of the column for the question (there is a box around that cell) | O8: bbk | P8: =COUNTIFS($D$16:$D$32,$O8,$H$16:$H$32,P$7) -> 2 | Q8: =COUNTIFS($D$16:$D$32,$O8,$H$16:$H$32,Q$7) -> 0 | R8: =COUNTIFS($D$16:$D$32,$O8,$H$16:$H$32,R$7) -> 1
B9: Write each formula so that it can be "dragged down" to the other cells in the column. | O9: tom ford | P9: =COUNTIFS($D$16:$D$32,$O9,$H$16:$H$32,P$7) -> 1 | Q9: =COUNTIFS($D$16:$D$32,$O9,$H$16:$H$32,Q$7) -> 2 | R9: =COUNTIFS($D$16:$D$32,$O9,$H$16:$H$32,R$7) -> 2
B10: The info at the right is for questions 9 and 10. See the test paper for more info. | O10: hilfigger | P10: =COUNTIFS($D$16:$D$32,$O10,$H$16:$H$32,P$7) -> 0 | Q10: =COUNTIFS($D$16:$D$32,$O10,$H$16:$H$32,Q$7) -> 1 | R10: =COUNTIFS($D$16:$D$32,$O10,$H$16:$H$32,R$7) -> 1
E11: NOTE: the formula for the answer to q2 is NOT typed below. | O11: cklein | P11: =COUNTIFS($D$16:$D$32,$O11,$H$16:$H$32,P$7) -> 5 | Q11: =COUNTIFS($D$16:$D$32,$O11,$H$16:$H$32,Q$7) -> 1 | R11: =COUNTIFS($D$16:$D$32,$O11,$H$16:$H$32,R$7) -> 1
E12: This is because the formula would generate random numbers and we want to show the same
E13: numbers below that are on the questions page. The acutal answer is shown in the summary to the right.
B14: q1 | I14: q2 | M14: q3 | N14: q4 | O14: q5 | P14: q6 | Q14: q7 | R14: q8 | S14: q9
B15: sku | C15: color | D15: mfr | E15: dept | F15: size | G15: season | H15: item | I15: full price SEE NOTE BELOW!!! | J15: when launched | K15: number sold this year | L15: amount in stock | M15: days on shelf SEE NOTE BELOW!!! | N15: reorder? | O15: sale price | P15: sale price | Q15: sale price | R15: average price of this type of item (eg. pants) | S15: price reduction based on color (see table)
B16: =LEFT(C16,1)&"-"&LEFT(D16,2)&"-"&F16&"-"&LEFT(H16,2) -> g-ck-s-ja | C16: green | D16: cklein | E16: girls | F16: s | G16: fall | H16: jacket | I16: 89.34 | J16: 45214 | K16: 363 | L16: 18 | M16: =DATE(2024,3,26)-J16 -> 163 | N16: =IF(L16<10%*K16,"reorder","") -> reorder | O16: {=_xlfn.IFS(M16>100,25%,M16>50,50%,M16>25,75%,TRUE,1)*I16} -> 22.335 | P16: =IF(AND(D16="hilfigger",OR(E16="mens",E16="womens")),50%,1)*I16 -> 89.34 | Q16: =IF(M16>AVERAGE($M$16:$M$32),50%,1)*I16 -> 44.67 | R16: =AVERAGEIFS($I$16:$I$32,$H$16:$H$32,H16) -> 93.538 | S16: =I16-VLOOKUP(C16,$K$4:$L$6,2,FALSE) -> 84.34
B17: =LEFT(C17,1)&"-"&LEFT(D17,2)&"-"&F17&"-"&LEFT(H17,2) -> y-ck-xl-sh | C17: yellow | D17: cklein | E17: boys | F17: xl | G17: winter | H17: shirt | I17: 85.12 | J17: 45276 | K17: 378 | L17: 9 | M17: =DATE(2024,3,26)-J17 -> 101 | N17: =IF(L17<10%*K17,"reorder","") -> reorder | O17: {=_xlfn.IFS(M17>100,25%,M17>50,50%,M17>25,75%,TRUE,1)*I17} -> 21.28 | P17: =IF(AND(D17="hilfigger",OR(E17="mens",E17="womens")),50%,1)*I17 -> 85.12 | Q17: =IF(M17>AVERAGE($M$16:$M$32),50%,1)*I17 -> 85.12 | R17: =AVERAGEIFS($I$16:$I$32,$H$16:$H$32,H17) -> 98.32 | S17: =I17-VLOOKUP(C17,$K$4:$L$6,2,FALSE) -> 75.12
B18: =LEFT(C18,1)&"-"&LEFT(D18,2)&"-"&F18&"-"&LEFT(H18,2) -> y-bb-m-ja | C18: yellow | D18: bbk | E18: girls | F18: m | G18: fall | H18: jacket | I18: 57.06 | J18: 45254 | K18: 377 | L18: 15 | M18: =DATE(2024,3,26)-J18 -> 123 | N18: =IF(L18<10%*K18,"reorder","") -> reorder | O18: {=_xlfn.IFS(M18>100,25%,M18>50,50%,M18>25,75%,TRUE,1)*I18} -> 14.265 | P18: =IF(AND(D18="hilfigger",OR(E18="mens",E18="womens")),50%,1)*I18 -> 57.06 | Q18: =IF(M18>AVERAGE($M$16:$M$32),50%,1)*I18 -> 28.53 | R18: =AVERAGEIFS($I$16:$I$32,$H$16:$H$32,H18) -> 93.538 | S18: =I18-VLOOKUP(C18,$K$4:$L$6,2,FALSE) -> 47.06
B19: =LEFT(C19,1)&"-"&LEFT(D19,2)&"-"&F19&"-"&LEFT(H19,2) -> y-bb-s-sh | C19: yellow | D19: bbk | E19: mens | F19: s | G19: summer | H19: shirt | I19: 60.63 | J19: 45324 | K19: 59 | L19: 8 | M19: =DATE(2024,3,26)-J19 -> 53 | N19: =IF(L19<10%*K19,"reorder","") | O19: {=_xlfn.IFS(M19>100,25%,M19>50,50%,M19>25,75%,TRUE,1)*I19} -> 30.315 | P19: =IF(AND(D19="hilfigger",OR(E19="mens",E19="womens")),50%,1)*I19 -> 60.63 | Q19: =IF(M19>AVERAGE($M$16:$M$32),50%,1)*I19 -> 60.63 | R19: =AVERAGEIFS($I$16:$I$32,$H$16:$H$32,H19) -> 98.32 | S19: =I19-VLOOKUP(C19,$K$4:$L$6,2,FALSE) -> 50.63
B20: =LEFT(C20,1)&"-"&LEFT(D20,2)&"-"&F20&"-"&LEFT(H20,2) -> y-to-s-ja | C20: yellow | D20: tom ford | E20: mens | F20: s | G20: fall | H20: jacket | I20: 64.76 | J20: 45265 | K20: 57 | L20: 9 | M20: =DATE(2024,3,26)-J20 -> 112 | N20: =IF(L20<10%*K20,"reorder","") | O20: {=_xlfn.IFS(M20>100,25%,M20>50,50%,M20>25,75%,TRUE,1)*I20} -> 16.19 | P20: =IF(AND(D20="hilfigger",OR(E20="mens",E20="womens")),50%,1)*I20 -> 64.76 | Q20: =IF(M20>AVERAGE($M$16:$M$32),50%,1)*I20 -> 32.38 | R20: =AVERAGEIFS($I$16:$I$32,$H$16:$H$32,H20) -> 93.538 | S20: =I20-VLOOKUP(C20,$K$4:$L$6,2,FALSE) -> 54.76
B21: =LEFT(C21,1)&"-"&LEFT(D21,2)&"-"&F21&"-"&LEFT(H21,2) -> y-to-m-pa | C21: yellow | D21: tom ford | E21: womens | F21: m | G21: summer | H21: pants | I21: 62.71 | J21: 45349 | K21: 391 | L21: 10 | M21: =DATE(2024,3,26)-J21 -> 28 | N21: =IF(L21<10%*K21,"reorder","") -> reorder | O21: {=_xlfn.IFS(M21>100,25%,M21>50,50%,M21>25,75%,TRUE,1)*I21} -> 47.0325 | P21: =IF(AND(D21="hilfigger",OR(E21="mens",E21="womens")),50%,1)*I21 -> 62.71 | Q21: =IF(M21>AVERAGE($M$16:$M$32),50%,1)*I21 -> 62.71 | R21: =AVERAGEIFS($I$16:$I$32,$H$16:$H$32,H21) -> 91.4375 | S21: =I21-VLOOKUP(C21,$K$4:$L$6,2,FALSE) -> 52.71
B22: =LEFT(C22,1)&"-"&LEFT(D22,2)&"-"&F22&"-"&LEFT(H22,2) -> y-ck-xl-pa | C22: yellow | D22: cklein | E22: girls | F22: xl | G22: summer | H22: pants | I22: 94.23 | J22: 45201 | K22: 147 | L22: 14 | M22: =DATE(2024,3,26)-J22 -> 176 | N22: =IF(L22<10%*K22,"reorder","") -> reorder | O22: {=_xlfn.IFS(M22>100,25%,M22>50,50%,M22>25,75%,TRUE,1)*I22} -> 23.5575 | P22: =IF(AND(D22="hilfigger",OR(E22="mens",E22="womens")),50%,1)*I22 -> 94.23 | Q22: =IF(M22>AVERAGE($M$16:$M$32),50%,1)*I22 -> 47.115 | R22: =AVERAGEIFS($I$16:$I$32,$H$16:$H$32,H22) -> 91.4375 | S22: =I22-VLOOKUP(C22,$K$4:$L$6,2,FALSE) -> 84.23
B23: =LEFT(C23,1)&"-"&LEFT(D23,2)&"-"&F23&"-"&LEFT(H23,2) -> g-ck-xl-sh | C23: green | D23: cklein | E23: womens | F23: xl | G23: spring | H23: shirt | I23: 113.56 | J23: 45266 | K23: 386 | L23: 5 | M23: =DATE(2024,3,26)-J23 -> 111 | N23: =IF(L23<10%*K23,"reorder","") -> reorder | O23: {=_xlfn.IFS(M23>100,25%,M23>50,50%,M23>25,75%,TRUE,1)*I23} -> 28.39 | P23: =IF(AND(D23="hilfigger",OR(E23="mens",E23="womens")),50%,1)*I23 -> 113.56 | Q23: =IF(M23>AVERAGE($M$16:$M$32),50%,1)*I23 -> 113.56 | R23: =AVERAGEIFS($I$16:$I$32,$H$16:$H$32,H23) -> 98.32 | S23: =I23-VLOOKUP(C23,$K$4:$L$6,2,FALSE) -> 108.56
B24: =LEFT(C24,1)&"-"&LEFT(D24,2)&"-"&F24&"-"&LEFT(H24,2) -> y-to-s-pa | C24: yellow | D24: tom ford | E24: girls | F24: s | G24: spring | H24: pants | I24: 120.15 | J24: 45316 | K24: 65 | L24: 14 | M24: =DATE(2024,3,26)-J24 -> 61 | N24: =IF(L24<10%*K24,"reorder","") | O24: {=_xlfn.IFS(M24>100,25%,M24>50,50%,M24>25,75%,TRUE,1)*I24} -> 60.075 | P24: =IF(AND(D24="hilfigger",OR(E24="mens",E24="womens")),50%,1)*I24 -> 120.15 | Q24: =IF(M24>AVERAGE($M$16:$M$32),50%,1)*I24 -> 120.15 | R24: =AVERAGEIFS($I$16:$I$32,$H$16:$H$32,H24) -> 91.4375 | S24: =I24-VLOOKUP(C24,$K$4:$L$6,2,FALSE) -> 110.15
B25: =LEFT(C25,1)&"-"&LEFT(D25,2)&"-"&F25&"-"&LEFT(H25,2) -> y-hi-xl-ja | C25: yellow | D25: hilfigger | E25: mens | F25: xl | G25: fall | H25: jacket | I25: 128.96 | J25: 45348 | K25: 444 | L25: 20 | M25: =DATE(2024,3,26)-J25 -> 29 | N25: =IF(L25<10%*K25,"reorder","") -> reorder | O25: {=_xlfn.IFS(M25>100,25%,M25>50,50%,M25>25,75%,TRUE,1)*I25} -> 96.72 | P25: =IF(AND(D25="hilfigger",OR(E25="mens",E25="womens")),50%,1)*I25 -> 64.48 | Q25: =IF(M25>AVERAGE($M$16:$M$32),50%,1)*I25 -> 128.96 | R25: =AVERAGEIFS($I$16:$I$32,$H$16:$H$32,H25) -> 93.538 | S25: =I25-VLOOKUP(C25,$K$4:$L$6,2,FALSE) -> 118.96
B26: =LEFT(C26,1)&"-"&LEFT(D26,2)&"-"&F26&"-"&LEFT(H26,2) -> y-ck-xl-sh | C26: yellow | D26: cklein | E26: boys | F26: xl | G26: winter | H26: shirt | I26: 121.76 | J26: 45235 | K26: 50 | L26: 14 | M26: =DATE(2024,3,26)-J26 -> 142 | N26: =IF(L26<10%*K26,"reorder","") | O26: {=_xlfn.IFS(M26>100,25%,M26>50,50%,M26>25,75%,TRUE,1)*I26} -> 30.44 | P26: =IF(AND(D26="hilfigger",OR(E26="mens",E26="womens")),50%,1)*I26 -> 121.76 | Q26: =IF(M26>AVERAGE($M$16:$M$32),50%,1)*I26 -> 60.88 | R26: =AVERAGEIFS($I$16:$I$32,$H$16:$H$32,H26) -> 98.32 | S26: =I26-VLOOKUP(C26,$K$4:$L$6,2,FALSE) -> 111.76
B27: =LEFT(C27,1)&"-"&LEFT(D27,2)&"-"&F27&"-"&LEFT(H27,2) -> b-ck-s-sh | C27: blue | D27: cklein | E27: mens | F27: s | G27: summer | H27: shirt | I27: 102.26 | J27: 45203 | K27: 185 | L27: 12 | M27: =DATE(2024,3,26)-J27 -> 174 | N27: =IF(L27<10%*K27,"reorder","") -> reorder | O27: {=_xlfn.IFS(M27>100,25%,M27>50,50%,M27>25,75%,TRUE,1)*I27} -> 25.565 | P27: =IF(AND(D27="hilfigger",OR(E27="mens",E27="womens")),50%,1)*I27 -> 102.26 | Q27: =IF(M27>AVERAGE($M$16:$M$32),50%,1)*I27 -> 51.13 | R27: =AVERAGEIFS($I$16:$I$32,$H$16:$H$32,H27) -> 98.32 | S27: =I27-VLOOKUP(C27,$K$4:$L$6,2,FALSE) -> 102.26
... B32: =LEFT(C32,1)&"-"&LEFT(D32,2)&"-"&F32&"-"&LEFT(H32,2) -> g-ck-xxxl-sh | C32: green | D32: cklein | E32: womens | F32: xxxl | G32: summer | H32: shirt | I32: 98.84 | J32: 45225 | K32: 423 | L32: 12 | M32: =DATE(2024,3,26)-J32 -> 152 | N32: =IF(L32<10%*K32,"reorder","") -> reorder | O32: {=_xlfn.IFS(M32>100,25%,M32>50,50%,M32>25,75%,TRUE,1)*I32} -> 24.71 | P32: =IF(AND(D32="hilfigger",OR(E32="mens",E32="womens")),50%,1)*I32 -> 98.84 | Q32: =IF(M32>AVERAGE($M$16:$M$32),50%,1)*I32 -> 49.42 | R32: =AVERAGEIFS($I$16:$I$32,$H$16:$H$32,H32) -> 98.32 | S32: =I32-VLOOKUP(C32,$K$4:$L$6,2,FALSE) -> 93.84
H34: NOTES:
I35: question number
I36: 2 | J36: The answer to question 2 should be as shown below:
K38: ANSWER | M38: FORMULATEXT
K39: =RANDBETWEEN(5000,19999)/100 -> 158.62 | M39: =_xlfn.FORMULATEXT(K39) -> =RANDBETWEEN(5000,19999)/100
J41: However, using randbetween would generate a new price for every cell in the column every time this file is opened.
J42: In order to see that the picture of the answers in the word document matches the data above, I didn't type in the formula.
J43: Rather I copied the actual numbers that were shown in the Word document.
J44: However, the correct answer is as shown above in this note.
I46: 3 | J46: This practice set comes from an exam that was originally given on March 26, 2024.
J47: The picture of the completed spreadsheet that appears in the Word document is how the results would have appeared on that day.
J48: Question 3 asked to write a formula to show the number of days that a product has been "on the shelf" until today.
...
